Workbook
Name Cooperativas_por_Provincia: #REF!

Sheet Sub-Total Rubros Argentina
A1: Rubro | B1: Total país | C1: Ajuste x Coop. Telefónicas
A2: Servicios Públicos | B2: 921 | C2: =ROUND(B2*$C$12/$B$12,0) -> 2412
A3: Agropecuarias | B3: 693 | C3: =ROUND(B3*$C$12/$B$12,0) -> 1815
A4: Consumo | B4: 366 | C4: =ROUND(B4*$C$12/$B$12,0) -> 958
A5: Trabajo | B5: 331 | C5: =ROUND(B5*$C$12/$B$12,0) -> 867
A6: Vivienda | B6: 195 | C6: =ROUND(B6*$C$12/$B$12,0) -> 511
A7: Provisión | B7: 138 | C7: =ROUND(B7*$C$12/$B$12,0) -> 361
A8: Bancarias | B8: 68 | C8: =ROUND(B8*$C$12/$B$12,0) -> 178
A9: Seguros | B9: 18 | C9: =ROUND(B9*$C$12/$B$12,0) -> 47
A10: Escolares | B10: 14 | C10: =ROUND(B10*$C$12/$B$12,0) -> 37
A11: Enseñanza | B11: 12 | C11: =ROUND(B11*$C$12/$B$12,0) -> 31
A12: Total | B12: =SUM(B2:B11) -> 2756 | C12: ='Sub-Total Subrubros Argentina'!C39 -> 7217

Sheet Sub-Total Subrubros Argentina
A1: Subrubro | B1: Total País | C1: Ajuste x Coop. Telefónicas
A2: Eléctricas | B2: 473 | C2: =ROUND(B2*$C$11/$B$11,0) -> 1239
A3: Agropecuarias | B3: 408 | C3: =ROUND(B3*$C$11/$B$11,0) -> 1069
A4: de Trabajo | B4: 331 | C4: =ROUND(B4*$C$11/$B$11,0) -> 867
A5: Ganaderas | B5: 197 | C5: =ROUND(B5*$C$11/$B$11,0) -> 516
A6: de Vivienda | B6: 195 | C6: =ROUND(B6*$C$11/$B$11,0) -> 511
A7: de Consumo | B7: 191 | C7: =ROUND(B7*$C$11/$B$11,0) -> 500
A8: de Servicios Públicos | B8: 175 | C8: =ROUND(B8*$C$11/$B$11,0) -> 458
A9: de Provisión | B9: 138 | C9: =ROUND(B9*$C$11/$B$11,0) -> 361
A10: de Agua | B10: 131 | C10: =ROUND(B10*$C$11/$B$11,0) -> 343
A11: Telefónicas | B11: 113 | C11: 296
A12: de Transporte | B12: 86 | C12: =ROUND(B12*$C$11/$B$11,0) -> 225
A13: Ahorro/Crédito/Emprend | B13: 68 | C13: =ROUND(B13*$C$11/$B$11,0) -> 178
A14: de Fletes/Remis/Taxis | B14: 44 | C14: =ROUND(B14*$C$11/$B$11,0) -> 115
A15: Vitivinícola | B15: 30 | C15: =ROUND(B15*$C$11/$B$11,0) -> 79
A16: Frutihortícolas | B16: 25 | C16: =ROUND(B16*$C$11/$B$11,0) -> 65
A17: de Salud: Medicina | B17: 18 | C17: =ROUND(B17*$C$11/$B$11,0) -> 47
A18: de Seguros | B18: 18 | C18: =ROUND(B18*$C$11/$B$11,0) -> 47
A19: de Escolares/Jardines | B19: 14 | C19: =ROUND(B19*$C$11/$B$11,0) -> 37
A20: de Asistencia Social | B20: 13 | C20: =ROUND(B20*$C$11/$B$11,0) -> 34
A21: Educación | B21: 12 | C21: =ROUND(B21*$C$11/$B$11,0) -> 31
A22: Arroceras | B22: 11 | C22: =ROUND(B22*$C$11/$B$11,0) -> 29
A23: de Salud: Farmacéuticas | B23: 9 | C23: =ROUND(B23*$C$11/$B$11,0) -> 24
... A38: de Bomberos | B38: 1 | C38: =ROUND(B38*$C$11/$B$11,0) -> 3
A39: Total | B39: =SUM(B2:B38) -> 2756 | C39: =SUM(C2:C38) -> 7217

Sheet Total de rubros por Provincia
A1: Provincia | B1: Rubro | C1: Total | D1: Ajuste x Coop. Telefónicas
A2: Buenos Aires | B2: Agropecuarias | C2: 146 | D2: =ROUND(C2*$D$177/$C$177,0) -> 382
A3: Buenos Aires | B3: Bancarias | C3: 22 | D3: =ROUND(C3*$D$177/$C$177,0) -> 58
A4: Buenos Aires | B4: Consumo | C4: 101 | D4: =ROUND(C4*$D$177/$C$177,0) -> 264
A5: Buenos Aires | B5: Enseñanza | C5: 1 | D5: =ROUND(C5*$D$177/$C$177,0) -> 3
A6: Buenos Aires | B6: Escolares | C6: 5 | D6: =ROUND(C6*$D$177/$C$177,0) -> 13
A7: Buenos Aires | B7: Provisión | C7: 52 | D7: =ROUND(C7*$D$177/$C$177,0) -> 136
A8: Buenos Aires | B8: Seguros | C8: 9 | D8: =ROUND(C8*$D$177/$C$177,0) -> 24
A9: Buenos Aires | B9: Servicios Públicos | C9: 278 | D9: =ROUND(C9*$D$177/$C$177,0) -> 728
A10: Buenos Aires | B10: Trabajo | C10: 105 | D10: =ROUND(C10*$D$177/$C$177,0) -> 275
A11: Buenos Aires | B11: Vivienda | C11: 47 | D11: =ROUND(C11*$D$177/$C$177,0) -> 123
A12: Total Buenos Aires | D12: =SUBTOTAL(9,D2:D11) -> 2006
A13: Capital | B13: Agropecuarias | C13: 2 | D13: =ROUND(C13*$D$177/$C$177,0) -> 5
A14: Capital | B14: Bancarias | C14: 23 | D14: =ROUND(C14*$D$177/$C$177,0) -> 60
A15: Capital | B15: Consumo | C15: 44 | D15: =ROUND(C15*$D$177/$C$177,0) -> 115
A16: Capital | B16: Provisión | C16: 3 | D16: =ROUND(C16*$D$177/$C$177,0) -> 8
A17: Capital | B17: Seguros | C17: 3 | D17: =ROUND(C17*$D$177/$C$177,0) -> 8
A18: Capital | B18: Servicios Públicos | C18: 4 | D18: =ROUND(C18*$D$177/$C$177,0) -> 10
A19: Capital | B19: Trabajo | C19: 22 | D19: =ROUND(C19*$D$177/$C$177,0) -> 58
A20: Capital | B20: Vivienda | C20: 46 | D20: =ROUND(C20*$D$177/$C$177,0) -> 120
A21: Total Capital | D21: =SUBTOTAL(9,D13:D20) -> 384
A22: Catamarca | B22: Agropecuarias | C22: 2 | D22: =ROUND(C22*$D$177/$C$177,0) -> 5
A23: Catamarca | B23: Consumo | C23: 1 | D23: =ROUND(C23*$D$177/$C$177,0) -> 3
A24: Catamarca | B24: Servicios Públicos | C24: 1 | D24: =ROUND(C24*$D$177/$C$177,0) -> 3
A25: Total Catamarca | D25: =SUBTOTAL(9,D22:D24) -> 11
A26: Córdoba | B26: Agropecuarias | C26: 136 | D26: =ROUND(C26*$D$177/$C$177,0) -> 356
A27: Córdoba | B27: Bancarias | C27: 6 | D27: =ROUND(C27*$D$177/$C$177,0) -> 16
A28: Córdoba | B28: Consumo | C28: 50 | D28: =ROUND(C28*$D$177/$C$177,0) -> 131
A29: Córdoba | B29: Enseñanza | C29: 7 | D29: =ROUND(C29*$D$177/$C$177,0) -> 18
A30: Córdoba | B30: Escolares | C30: 3 | D30: =ROUND(C30*$D$177/$C$177,0) -> 8
A31: Córdoba | B31: Provisión | C31: 19 | D31: =ROUND(C31*$D$177/$C$177,0) -> 50
A32: Córdoba | B32: Seguros | C32: 2 | D32: =ROUND(C32*$D$177/$C$177,0) -> 5
A33: Córdoba | B33: Servicios Públicos | C33: 260 | D33: =ROUND(C33*$D$177/$C$177,0) -> 681
A34: Córdoba | B34: Trabajo | C34: 54 | D34: =ROUND(C34*$D$177/$C$177,0) -> 141
A35: Córdoba | B35: Vivienda | C35: 35 | D35: =ROUND(C35*$D$177/$C$177,0) -> 92
A36: Total Córdoba | D36: =SUBTOTAL(9,D26:D35) -> 1498
A37: Corrientes | B37: Agropecuarias | C37: 11 | D37: =ROUND(C37*$D$177/$C$177,0) -> 29
A38: Corrientes | B38: Consumo | C38: 6 | D38: =ROUND(C38*$D$177/$C$177,0) -> 16
A39: Corrientes | B39: Servicios Públicos | C39: 3 | D39: =ROUND(C39*$D$177/$C$177,0) -> 8
A40: Corrientes | B40: Trabajo | C40: 3 | D40: =ROUND(C40*$D$177/$C$177,0) -> 8
...

Sheet Total de sub-rubros por Provinc
A1: Provincia | B1: Subrubro | C1: Total | D1: Ajuste x Coop. Telefónicas
A2: Buenos Aires | B2: Agropecuarias | C2: 113 | D2: =ROUND(C2*$D$325/$C$325,0) -> 296
A3: Buenos Aires | B3: Ahorro/Crédito/Emprend | C3: 22 | D3: =ROUND(C3*$D$325/$C$325,0) -> 58
A4: Buenos Aires | B4: Apícolas | C4: 2 | D4: =ROUND(C4*$D$325/$C$325,0) -> 5
A5: Buenos Aires | B5: Avícolas | C5: 2 | D5: =ROUND(C5*$D$325/$C$325,0) -> 5
A6: Buenos Aires | B6: de Agua | C6: 23 | D6: =ROUND(C6*$D$325/$C$325,0) -> 60
A7: Buenos Aires | B7: de Asistencia Social | C7: 1 | D7: =ROUND(C7*$D$325/$C$325,0) -> 3
A8: Buenos Aires | B8: de Bomberos | C8: 1 | D8: =ROUND(C8*$D$325/$C$325,0) -> 3
A9: Buenos Aires | B9: de Carniceros | C9: 2 | D9: =ROUND(C9*$D$325/$C$325,0) -> 5
A10: Buenos Aires | B10: de Comercio | C10: 1 | D10: =ROUND(C10*$D$325/$C$325,0) -> 3
A11: Buenos Aires | B11: de Consumo | C11: 56 | D11: =ROUND(C11*$D$325/$C$325,0) -> 147
A12: Buenos Aires | B12: de Escolares/Jardines | C12: 5 | D12: =ROUND(C12*$D$325/$C$325,0) -> 13
A13: Buenos Aires | B13: de Fletes/Remis/Taxis | C13: 9 | D13: =ROUND(C13*$D$325/$C$325,0) -> 24
... A31: Buenos Aires | B31: Textiles | C31: 2 | D31: =ROUND(C31*$D$325/$C$325,0) -> 5
A32: Total Buenos Aires | D32: =SUBTOTAL(9,D2:D31) -> 2007
A33: Capital | B33: Agropecuarias | C33: 1 | D33: =ROUND(C33*$D$325/$C$325,0) -> 3
A34: Capital | B34: Ahorro/Crédito/Emprend | C34: 23 | D34: =ROUND(C34*$D$325/$C$325,0) -> 60
A35: Capital | B35: de Asistencia Social | C35: 1 | D35: =ROUND(C35*$D$325/$C$325,0) -> 3
A36: Capital | B36: de Consumo | C36: 31 | D36: =ROUND(C36*$D$325/$C$325,0) -> 81
A37: Capital | B37: de Fletes/Remis/Taxis | C37: 5 | D37: =ROUND(C37*$D$325/$C$325,0) -> 13
A38: Capital | B38: de Provisión | C38: 3 | D38: =ROUND(C38*$D$325/$C$325,0) -> 8
A39: Capital | B39: de Salud: Medicina | C39: 2 | D39: =ROUND(C39*$D$325/$C$325,0) -> 5
A40: Capital | B40: de Salud: Salud | C40: 2 | D40: =ROUND(C40*$D$325/$C$325,0) -> 5
A41: Capital | B41: de Seguros | C41: 3 | D41: =ROUND(C41*$D$325/$C$325,0) -> 8
A42: Capital | B42: de Servicios Públicos | C42: 2 | D42: =ROUND(C42*$D$325/$C$325,0) -> 5
A43: Capital | B43: de Trabajo | C43: 22 | D43: =ROUND(C43*$D$325/$C$325,0) -> 58
A44: Capital | B44: de Transporte | C44: 4 | D44: =ROUND(C44*$D$325/$C$325,0) -> 10
... A47: Capital | B47: Floricultoras | C47: 1 | D47: =ROUND(C47*$D$325/$C$325,0) -> 3
A48: Total Capital | D48: =SUBTOTAL(9,D33:D47) -> 385
A49: Catamarca | B49: Agropecuarias | C49: 1 | D49: =ROUND(C49*$D$325/$C$325,0) -> 3
A50: Catamarca | B50: de Transporte | C50: 1 | D50: =ROUND(C50*$D$325/$C$325,0) -> 3
A51: Catamarca | B51: Ganaderas | C51: 1 | D51: =ROUND(C51*$D$325/$C$325,0) -> 3
A52: Catamarca | B52: Telefónicas | C52: 1 | D52: =ROUND(C52*$D$325/$C$325,0) -> 3
A53: Total Catamarca | D53: =SUBTOTAL(9,D49:D52) -> 12
A54: Córdoba | B54: Agropecuarias | C54: 59 | D54: =ROUND(C54*$D$325/$C$325,0) -> 155
A55: Córdoba | B55: Ahorro/Crédito/Emprend | C55: 6 | D55: =ROUND(C55*$D$325/$C$325,0) -> 16
A56: Córdoba | B56: de Agua | C56: 24 | D56: =ROUND(C56*$D$325/$C$325,0) -> 63
A57: Córdoba | B57: de Asistencia Social | C57: 1 | D57: =ROUND(C57*$D$325/$C$325,0) -> 3
A58: Córdoba | B58: de Consumo | C58: 31 | D58: =ROUND(C58*$D$325/$C$325,0) -> 81
A59: Córdoba | B59: de Escolares/Jardines | C59: 3 | D59: =ROUND(C59*$D$325/$C$325,0) -> 8
...

Sheet Est. Res. Proy.
A1: YERBANALYTICS
A2: Sistema de monitoreo, diagnostico y actuacion para viveros de yerba mate
A3: Estado de resultados
A5: Inversión Inicial: | B5: 79000000
A7: Período | B7: Año 0 | J7: Año 1 | K7: Año 2
A8: Concepto | B8: Start-up | C8: 1 | D8: 2 | E8: 3 | F8: 4 | G8: 5 | H8: 6 | I8: 7 | J8: 1-12 | K8: 1-12
A9: Ingresos | B9: =Ingresos!B18 -> 79000000 | C9: =Ingresos!C18 -> 0 | D9: =Ingresos!D18 -> 0 | E9: =Ingresos!E18 -> 0 | F9: =Ingresos!F18 -> 0 | G9: =Ingresos!G18 -> 0 | H9: =Ingresos!H18 -> 0 | I9: =Ingresos!I18 -> 0 | ... K9: =Ingresos!K18 -> 524214900
A10: Egresos | B10: =Egresos!B21 -> 36641319 | C10: =Egresos!C21 -> 5581318.7 | D10: =Egresos!D21 -> 5581318.7 | E10: =Egresos!E21 -> 5581318.7 | F10: =Egresos!F21 -> 5581318.7 | G10: =Egresos!G21 -> 5581318.7 | H10: =Egresos!H21 -> 5731318.7 | I10: =Egresos!I21 -> 7132508 | ... K10: =Egresos!K21 -> 4.2342906e+08
A11: Resultado Bruto | B11: =B9-B10 -> 42358681 | C11: =C9-C10 -> -5581318.7 | D11: =D9-D10 -> -5581318.7 | E11: =E9-E10 -> -5581318.7 | F11: =F9-F10 -> -5581318.7 | G11: =G9-G10 -> -5581318.7 | H11: =H9-H10 -> -5731318.7 | I11: =I9-I10 -> -7132508 | ... K11: =K9-K10 -> 1.0078584e+08
A12: Impuesto a los Ingresos Brutos (3,8%) | B12: =B9*-3.8% -> -3002000 | C12: =C9*-3.8% -> 0 | D12: =D9*-3.8% -> 0 | E12: =E9*-3.8% -> 0 | F12: =F9*-3.8% -> 0 | G12: =G9*-3.8% -> 0 | H12: =H9*-3.8% -> 0 | I12: =I9*-3.8% -> 0 | ... K12: =K9*-3.8% -> -19920166
A13: Impuesto a los débitos y créditos bancarios | B13: =IF((B9-B10)<0,(B9-B10)*0.016,(B9-B10)*-0.016) -> -677738.9 | C13: =IF((C9-C10)<0,(C9-C10)*0.016,(C9-C10)*-0.016) -> -89301.099 | D13: =IF((D9-D10)<0,(D9-D10)*0.016,(D9-D10)*-0.016) -> -89301.099 | E13: =IF((E9-E10)<0,(E9-E10)*0.016,(E9-E10)*-0.016) -> -89301.099 | F13: =IF((F9-F10)<0,(F9-F10)*0.016,(F9-F10)*-0.016) -> -89301.099 | G13: =IF((G9-G10)<0,(G9-G10)*0.016,(G9-G10)*-0.016) -> -89301.099 | H13: =IF((H9-H10)<0,(H9-H10)*0.016,(H9-H10)*-0.016) -> -91701.099 | I13: =IF((I9-I10)<0,(I9-I10)*0.016,(I9-I10)*-0.016) -> -114120.13 | ... K13: =IF((K9-K10)<0,(K9-K10)*0.016,(K9-K10)*-0.016) -> -1612573.5
A14: Resultado Neto antes de impuestos e intereses | B14: =IF(B11<0,B11+B12+B13,B11-B12-B13) -> 46038420 | C14: =IF(C11<0,C11+C12+C13,C11-C12-C13) -> -5670619.8 | D14: =IF(D11<0,D11+D12+D13,D11-D12-D13) -> -5670619.8 | E14: =IF(E11<0,E11+E12+E13,E11-E12-E13) -> -5670619.8 | F14: =IF(F11<0,F11+F12+F13,F11-F12-F13) -> -5670619.8 | G14: =IF(G11<0,G11+G12+G13,G11-G12-G13) -> -5670619.8 | H14: =IF(H11<0,H11+H12+H13,H11-H12-H13) -> -5823019.8 | I14: =IF(I11<0,I11+I12+I13,I11-I12-I13) -> -7246628.1 | ... K14: =IF(K11<0,K11+K12+K13,K11-K12-K13) -> 1.2231858e+08
A15: Gastos financieros (amortizaciones, creditos etc) | B15: N/A | C15: =Amortizaciones!C20 -> 1272833.3 | D15: =C15 -> 1272833.3 | E15: =D15 -> 1272833.3 | F15: =E15 -> 1272833.3 | G15: =F15 -> 1272833.3 | H15: =G15 -> 1272833.3 | I15: =H15 -> 1272833.3 | J15: 0 | K15: 0
A16: Resultado Neto antes de impuesto a las ganancias | B16: =B14 -> 46038420 | C16: =IF(C14<0,C14+C15,C14-C15) -> -4397786.5 | D16: =IF(D14<0,D14+D15,D14-D15) -> -4397786.5 | E16: =IF(E14<0,E14+E15,E14-E15) -> -4397786.5 | F16: =IF(F14<0,F14+F15,F14-F15) -> -4397786.5 | G16: =IF(G14<0,G14+G15,G14-G15) -> -4397786.5 | H16: =IF(H14<0,H14+H15,H14-H15) -> -4550186.5 | I16: =IF(I14<0,I14+I15,I14-I15) -> -5973794.8 | J16: =IF(J14<0,J14+J15,J14-J15) -> -35691267 | K16: =IF(K14<0,K14+K15,K14-K15) -> 1.2231858e+08
A17: Impuesto a las ganancias (35%) | B17: N/A | C17: =IF(C16<0,0,C16*35%) -> 0 | D17: =IF(D16<0,0,D16*35%) -> 0 | E17: =IF(E16<0,0,E16*35%) -> 0 | F17: =IF(F16<0,0,F16*35%) -> 0 | G17: =IF(G16<0,0,G16*35%) -> 0 | H17: =IF(H16<0,0,H16*35%) -> 0 | I17: =IF(I16<0,0,I16*35%) -> 0 | J17: =IF(J16<0,0,J16*35%) -> 0 | K17: =IF(K16<0,0,K16*35%) -> 42811503
A18: Resultado Neto Acumulado | B18: =B16 -> 46038420 | C18: =B18+C16-C17 -> 41640634 | D18: =C18+D16-D17 -> 37242847 | E18: =D18+E16-E17 -> 32845061 | F18: =E18+F16-F17 -> 28447274 | G18: =F18+G16-G17 -> 24049488 | H18: =G18+H16-H17 -> 19499301 | I18: =H18+I16-I17 -> 13525507 | J18: =J16-J17 -> -35691267 | K18: =K16-K17 -> 79507078
A20: Resultado Final Acumulado Descontado | B20: =SUM(I18:K18) -> 57341317 | C20: Tasa de corte: | E20: 0.3 | H20: Inversion inicial | I20: Año 0 | J20: Año 1 | K20: Año 2
G21: Flujo de fondo | H21: =-B5 -> -79000000 | I21: =I18 -> 13525507 | J21: =J18 -> -35691267 | K21: =K18 -> 79507078
A22: Valor Neto Actual | B22: {=NPV(E20,H21:K21)} -> -41173791
A24: Tasa Interna de Retorno | B24: =IRR(H21:K21) -> -0.096326407

Sheet Ingresos
A1: YERBANALYTICS - Planilla de Ingresos
A2: Planilla de Ingresos
A4: Mercado Objetivo (NEA: Misiones y Corrientes) | C4: Usuarios | D4: Facturacion | E4: Inversion | G4: Users | H4: Monthly Bill
A5: Viveros yerbateros dedicados | C5: 40 | D5: 864000000 | E5: 0.35 | G5: Viveros | H5: 1800000
A6: Cooperativas con vivero central | C6: 25 | D6: 540000000 | E6: 0.35 | G6: Cooperativas | H6: 1800000
A7: Productores con vivero propio | C7: 120 | D7: 1296000000 | E7: 0.2 | G7: Productores | H7: 900000
A8: - | C8: 0 | D8: 0 | G8: 80000
A9: Total mercado potencial | C9: 185
A10: Total | C10: =SUM(C5:C8) -> 185 | D10: =SUM(D5:D9) -> 2700000000 | G10: =SUM(G5:H8) -> 4580000
A12: Periodo | C12: Año 0 | J12: Año 1 | K12: Año 2 | L12: Total Acumulado
B13: Start-up | C13: 1 | D13: 2 | E13: 3 | F13: 4 | G13: 5 | H13: 6 | I13: 7 | J13: 1-12 | K13: 1-12 | L13: 3 años
A14: Aporte de Socios | B14: ='Est. Res. Proy.'!B5 -> 79000000 | C14: 0 | D14: 0 | E14: 0 | F14: 0 | G14: 0 | H14: 0 | I14: 0 | J14: 0 | K14: 0 | L14: =SUM(B14:K14) -> 79000000
A15: Venta de simuladores | B15: 0 | C15: 0 | D15: 0 | E15: 0 | F15: 0 | G15: 0 | H15: 0 | I15: 0 | J15: =C24*B24 -> 79917000 | K15: =D24*E24 -> 242414900 | L15: =SUM(B15:K15) -> 322331900
A16: Suscripción a soporte | B16: =B15*$C$20 -> 0 | C16: 0 | D16: 0 | E16: 0 | F16: 0 | G16: 0 | H16: 0 | I16: 0 | J16: =C25*B25*12 -> 64800000 | K16: =D25*E25*12 -> 280800000 | L16: =SUM(B16:K16) -> 345600000
A17: Jornadas de capacitación | B17: =B15*$C$20 -> 0 | C17: 0 | D17: 0 | E17: 0 | F17: 0 | G17: 0 | H17: 0 | I17: 0 | J17: 600000 | K17: 1000000 | L17: =SUM(B17:K17) -> 1600000
A18: Total Ingresos | B18: =SUM(B14:B17) -> 79000000 | C18: =SUM(C14:C17) -> 0 | D18: =SUM(D14:D17) -> 0 | E18: =SUM(E14:E17) -> 0 | F18: =SUM(F14:F17) -> 0 | G18: =SUM(G14:G17) -> 0 | H18: =SUM(H14:H17) -> 0 | I18: =SUM(I14:I17) -> 0 | ... L18: =SUM(L14:L17) -> 748531900
A22: Detalle | B22: Precio de venta x Unidad | C22: Cantidad de Ventas | D22: Precio de venta x Unidad | E22: Cantidad de Ventas
B23: Año 1 | C23: Año 1 | D23: Año 2 | E23: Año 2
A24: Simulador | B24: 26639000 | C24: 3 | D24: =B24+B24*'Est. Res. Proy.'!E20 -> 34630700 | E24: 7
A25: Soporte mensual | B25: 1800000 | C25: 3 | D25: =B25+B25*'Est. Res. Proy.'!E20 -> 2340000 | E25: =C25+E24 -> 10

Sheet Egresos
A1: ='Est. Res. Proy.'!A2 -> Sistema de monitoreo, diagnostico y actuacion para viveros de yerba mate
A2: Planilla de Gastos
A4: Período | C4: Año 0 | J4: Año 1 | K4: Año 2 | L4: Total
A5: Concepto | B5: Start-up | C5: 1 | D5: 2 | E5: 3 | F5: 4 | G5: 5 | H5: 6 | I5: 7 | J5: 1-12 | K5: 1-12 | L5: 1-6
A6: Recursos Humanos | B6: =RRHH!C30 -> 4826318.7 | C6: =RRHH!D30 -> 4826318.7 | D6: =RRHH!E30 -> 4826318.7 | E6: =RRHH!F30 -> 4826318.7 | F6: =RRHH!G30 -> 4826318.7 | G6: =RRHH!H30 -> 4826318.7 | H6: =RRHH!I30 -> 4826318.7 | I6: =RRHH!J30 -> 6227508 | ... K6: =RRHH!L30 -> 1.8562956e+08 | L6: =SUM(B6:K6) -> 3.1531741e+08
A7: Muebles y Utiles | B7: =Inversiones!D11 -> 1060000 | C7: 0 | D7: 0 | E7: 0 | F7: 0 | G7: 0 | H7: 0 | I7: 0 | J7: 0 | K7: 0 | L7: =SUM(B7:K7) -> 1060000
A8: Equipamiento | B8: =Inversiones!D20 -> 6760000 | C8: 0 | D8: 0 | E8: 0 | F8: 0 | G8: 0 | H8: 0 | I8: 0 | J8: 0 | K8: 0 | L8: =SUM(B8:K8) -> 6760000
A9: Equipamiento Simulador | B9: =Inversiones!D44 -> 23785000 | C9: 0 | D9: 0 | E9: 0 | F9: 0 | G9: 0 | H9: 0 | I9: 0 | J9: =C37*B37 -> 71355000 | K9: =E37*D37 -> 216443500 | L9: =SUM(B9:K9) -> 311583500
A10: Alquiler de Oficina | B10: 0 | C10: 350000 | D10: 350000 | E10: 350000 | F10: 350000 | G10: 350000 | H10: 350000 | I10: 350000 | J10: 4200000 | K10: 5040000 | L10: =SUM(B10:K10) -> 11690000
A11: Expensas | B11: 0 | C11: 40000 | D11: 40000 | E11: 40000 | F11: 40000 | G11: 40000 | H11: 40000 | I11: 40000 | J11: 480000 | K11: 576000 | L11: =SUM(B11:K11) -> 1336000
A12: Servicios Públicos e Impuestos | B12: 60000 | C12: 60000 | D12: 60000 | E12: 60000 | F12: 60000 | G12: 60000 | H12: 60000 | I12: 60000 | J12: 720000 | K12: 864000 | L12: =SUM(B12:K12) -> 2064000
A13: Papeleria y útiles | B13: 0 | C13: 15000 | D13: 15000 | E13: 15000 | F13: 15000 | G13: 15000 | H13: 15000 | I13: 15000 | J13: 180000 | K13: 216000 | L13: =SUM(B13:K13) -> 501000
A14: Telefono y Celulares | B14: 50000 | C14: 50000 | D14: 50000 | E14: 50000 | F14: 50000 | G14: 50000 | H14: 50000 | I14: 50000 | J14: 600000 | K14: 720000 | L14: =SUM(B14:K14) -> 1720000
A15: Movilidad y Viaticos | B15: 0 | C15: 80000 | D15: 80000 | E15: 80000 | F15: 80000 | G15: 80000 | H15: 80000 | I15: 80000 | J15: 2400000 | K15: 5600000 | L15: =SUM(B15:K15) -> 8560000
A16: Seguros (1% de Activos) | B16: 0 | C16: 0 | D16: 0 | E16: 0 | F16: 0 | G16: 0 | H16: 0 | I16: 0 | J16: 400000 | K16: 700000 | L16: =SUM(B16:K16) -> 1100000
A17: Conexión a Internet | B17: 100000 | C17: 100000 | D17: 100000 | E17: 100000 | F17: 100000 | G17: 100000 | H17: 100000 | I17: 100000 | J17: 1200000 | K17: 1440000 | L17: =SUM(B17:K17) -> 3440000
A18: Proveedores | B18: 0 | C18: 60000 | D18: 60000 | E18: 60000 | F18: 60000 | G18: 60000 | H18: 60000 | I18: 60000 | J18: 1800000 | K18: 3200000 | L18: =SUM(B18:K18) -> 5420000
A19: Campaña de Marketing | B19: 0 | C19: 0 | D19: 0 | E19: 0 | F19: 0 | G19: 0 | H19: 150000 | I19: 150000 | J19: 2000000 | K19: 3000000 | L19: =SUM(B19:K19) -> 5300000
L20: =SUM(B20:K20) -> 0
A21: Total de Egresos | B21: =SUM(B6:B20) -> 36641319 | C21: =SUM(C6:C20) -> 5581318.7 | D21: =SUM(D6:D20) -> 5581318.7 | E21: =SUM(E6:E20) -> 5581318.7 | F21: =SUM(F6:F20) -> 5581318.7 | G21: =SUM(G6:G20) -> 5581318.7 | H21: =SUM(H6:H20) -> 5731318.7 | I21: =SUM(I6:I20) -> 7132508 | ... L21: =SUM(L6:L20) -> 6.7585191e+08
A24: Análisis del crédito bancario
A25: Sistema de Amortización Pago Único
A26: Capital | B26: N/A
A27: Tasa de interés | B27: N/A | C27: TEM
A28: Cantidad de periodos | B28: N/A
A29: Monto final préstamo
A30: Monto por mes en base a periodo
I31: |
A35: Detalle | B35: Costo x Unidad | C35: Cantidad de unidades fabricadas | D35: Costo x Unidad | E35: Cantidad de unidades fabricadas
B36: Año 1 | C36: Año 1 | D36: Año 2 | E36: Año 2
A37: Costo por Producto X | B37: =Inversiones!D44/Inversiones!C29 -> 23785000 | C37: 3 | D37: =B37+B37*'Est. Res. Proy.'!E20 -> 30920500 | E37: 7

Sheet RRHH
A1: ='Est. Res. Proy.'!A2 -> Sistema de monitoreo, diagnostico y actuacion para viveros de yerba mate
A2: Recursos Humanos
A4: Período | B4: Sueldo | C4: Cargas | D4: Sueldo | E4: Aguinaldo | F4: Vacaciones | G4: Merma | H4: Ausentismo | I4: Costo Laboral | J4: Start-up | K4: Año 0 | R4: Año 1 | S4: Año 2 | T4: Total
A5: Concepto | B5: Neto | C5: Sociales | D5: c/Impuestos | E5: Prorrateado | F5: Licencias | G5: Productividad | I5: Unitario Total | K5: 1 | L5: 2 | M5: 3 | N5: 4 | O5: 5 | P5: 6 | Q5: 7 | R5: 1-12 | S5: 1-12
A6: Lider de Proyecto / Product Owner (fundador) | B6: 900000 | C6: =B6*$B$15 -> 171000 | D6: =B6+C6 -> 1071000 | E6: =D6*$B$16 -> 89214.3 | F6: =D6*$B$17 -> 89214.3 | G6: =D6*$B$18 -> 107100 | H6: =D6*$B$19 -> 44660.7 | I6: =SUM(D6:H6) -> 1401189.3 | J6: 1 | K6: =J6 -> 1 | L6: =K6 -> 1 | M6: =L6 -> 1 | N6: =M6 -> 1 | O6: =N6 -> 1 | P6: =O6 -> 1 | Q6: 1 | R6: 12 | S6: 12 | T6: =SUM(J6:S6) -> 32
A7: Desarrollador (full-stack / IoT) | B7: 1000000 | C7: =B7*$B$15 -> 190000 | D7: =B7+C7 -> 1190000 | E7: =D7*$B$16 -> 99127 | F7: =D7*$B$17 -> 99127 | G7: =D7*$B$18 -> 119000 | H7: =D7*$B$19 -> 49623 | I7: =SUM(D7:H7) -> 1556877 | J7: 1 | K7: =J7 -> 1 | L7: =K7 -> 1 | M7: =L7 -> 1 | N7: =M7 -> 1 | O7: =N7 -> 1 | P7: =O7 -> 1 | Q7: =P7 -> 1 | R7: 12 | S7: 24 | T7: =SUM(J7:S7) -> 44
A8: Ingeniero de IA / ML (fundador) | B8: 1200000 | C8: =B8*$B$15 -> 228000 | D8: =B8+C8 -> 1428000 | E8: =D8*$B$16 -> 118952.4 | F8: =D8*$B$17 -> 118952.4 | G8: =D8*$B$18 -> 142800 | H8: =D8*$B$19 -> 59547.6 | I8: =SUM(D8:H8) -> 1868252.4 | J8: 1 | K8: =J8 -> 1 | L8: =K8 -> 1 | M8: =L8 -> 1 | N8: =M8 -> 1 | O8: =N8 -> 1 | P8: =O8 -> 1 | Q8: =P8 -> 1 | R8: 12 | S8: 12 | T8: =SUM(J8:S8) -> 32
A9: Tecnico de Soporte e Instalacion | B9: 900000 | C9: =B9*$B$15 -> 171000 | D9: =B9+C9 -> 1071000 | E9: =D9*$B$16 -> 89214.3 | F9: =D9*$B$17 -> 89214.3 | G9: =D9*$B$18 -> 107100 | H9: =D9*$B$19 -> 44660.7 | I9: =SUM(D9:H9) -> 1401189.3 | J9: 0 | K9: 0 | L9: 0 | M9: 0 | N9: 0 | O9: 0 | P9: 0 | Q9: 1 | R9: 12 | S9: 24 | T9: =SUM(J9:S9) -> 37
A10: Responsable Comercial / Marketing | B10: 1000000 | C10: =B10*$B$15 -> 190000 | D10: =B10+C10 -> 1190000 | E10: =D10*$B$16 -> 99127 | F10: =D10*$B$17 -> 99127 | G10: =D10*$B$18 -> 119000 | H10: =D10*$B$19 -> 49623 | I10: =SUM(D10:H10) -> 1556877 | J10: 0 | K10: 0 | L10: 0 | M10: 0 | N10: 0 | O10: 0 | P10: 0 | Q10: 0 | R10: 0 | S10: 12 | T10: =SUM(J10:S10) -> 12
A11: Total de Recursos Humanos | B11: =SUM(B6:B10) -> 5000000 | C11: =SUM(C6:C10) -> 950000 | D11: =SUM(D6:D10) -> 5950000 | E11: =SUM(E6:E10) -> 495635 | F11: =SUM(F6:F10) -> 495635 | G11: =SUM(G6:G10) -> 595000 | H11: =SUM(H6:H10) -> 248115 | I11: =SUM(I6:I10) -> 7784385 | ... T11: =SUM(T6:T10) -> 157
A13: Parametros de Cálculo
A15: Cargas Sociales | B15: 0.19
A16: Aguinaldo | B16: 0.0833
A17: Vacaciones y Licencias | B17: 0.0833
A18: Merma de Productividad | B18: 0.1
A19: Ausentismo | B19: 0.0417
A21: Costos Laborales | B21: Se aplica un 20% de aumento en el costo laboral del segundo y tercer año.
A23: Período | B23: Costo | C23: Star-up | D23: Año 0 | K23: Año 1 | L23: Año 2 | M23: Total
A24: Concepto | B24: Laboral | D24: 1 | E24: 2 | F24: 3 | G24: 4 | H24: 5 | I24: 6 | J24: 7 | K24: 1-12 | L24: 1-12 | M24: Uso
A25: Product Owner | B25: =I6 -> 1401189.3 | C25: =$B$25*J6 -> 1401189.3 | D25: =$B$25*K6 -> 1401189.3 | E25: =$B$25*L6 -> 1401189.3 | F25: =$B$25*M6 -> 1401189.3 | G25: =$B$25*N6 -> 1401189.3 | H25: =$B$25*O6 -> 1401189.3 | I25: =$B$25*P6 -> 1401189.3 | J25: =$B$25*Q6 -> 1401189.3 | K25: =B25*1.2*R6 -> 20177126 | L25: =B25*1.2*1.2*S6 -> 24212551 | M25: =SUM(D25:L25) -> 54198002
A26: Desarrollador | B26: =I7 -> 1556877 | C26: =$B$26*J7 -> 1556877 | D26: =$B$26*K7 -> 1556877 | E26: =$B$26*L7 -> 1556877 | F26: =$B$26*M7 -> 1556877 | G26: =$B$26*N7 -> 1556877 | H26: =$B$26*O7 -> 1556877 | I26: =$B$26*P7 -> 1556877 | J26: =$B$26*Q7 -> 1556877 | K26: =B26*1.2*R7 -> 22419029 | L26: =B26*1.2*1.2*S7 -> 53805669 | M26: =SUM(D26:L26) -> 87122837
A27: Scrum Master | B27: =I8 -> 1868252.4 | C27: =$B$27*J8 -> 1868252.4 | D27: =$B$27*K8 -> 1868252.4 | E27: =$B$27*L8 -> 1868252.4 | F27: =$B$27*M8 -> 1868252.4 | G27: =$B$27*N8 -> 1868252.4 | H27: =$B$27*O8 -> 1868252.4 | I27: =$B$27*P8 -> 1868252.4 | J27: =$B$27*Q8 -> 1868252.4 | K27: =B27*1.2*R8 -> 26902835 | L27: =B27*1.2*1.2*S8 -> 32283401 | M27: =SUM(D27:L27) -> 72264003
A28: Técnico de soporte | B28: =I9 -> 1401189.3 | C28: =$B$28*J9 -> 0 | D28: =$B$28*K9 -> 0 | E28: =$B$28*L9 -> 0 | F28: =$B$28*M9 -> 0 | G28: =$B$28*N9 -> 0 | H28: =$B$28*O9 -> 0 | I28: =$B$28*P9 -> 0 | J28: =$B$28*Q9 -> 1401189.3 | K28: =B28*1.2*R9 -> 20177126 | L28: =B28*1.2*1.2*S9 -> 48425102 | M28: =SUM(D28:L28) -> 70003417
A29: Gerente de Marketing | B29: =I10 -> 1556877 | C29: =$B$29*J10 -> 0 | D29: =$B$29*K10 -> 0 | E29: =$B$29*L10 -> 0 | F29: =$B$29*M10 -> 0 | G29: =$B$29*N10 -> 0 | H29: =$B$29*O10 -> 0 | I29: =$B$29*P10 -> 0 | J29: =$B$29*Q10 -> 0 | K29: =B29*1.2*R10 -> 0 | L29: =B29*1.2*1.2*S10 -> 26902835 | M29: =SUM(D29:L29) -> 26902835
A30: Totales Costo Laboral | B30: =SUM(B25:B29) -> 7784385 | C30: =SUM(C24:C29) -> 4826318.7 | D30: =SUM(D25:D29) -> 4826318.7 | E30: =SUM(E25:E29) -> 4826318.7 | F30: =SUM(F25:F29) -> 4826318.7 | G30: =SUM(G25:G29) -> 4826318.7 | H30: =SUM(H25:H29) -> 4826318.7 | I30: =SUM(I25:I29) -> 4826318.7 | J30: =SUM(J25:J29) -> 6227508 | K30: =SUM(K25:K29) -> 89676115 | L30: =SUM(L25:L29) -> 1.8562956e+08 | M30: =SUM(C30:L30) -> 3.1531741e+08

Sheet Inversiones
A1: ='Est. Res. Proy.'!A2 -> Sistema de monitoreo, diagnostico y actuacion para viveros de yerba mate
A2: Inversiones
A4: Período | D4: Startup
A5: Concepto | B5: Costo | C5: Cantidad
A6: Escritorios | B6: 120000 | C6: 4 | D6: =B6*C6 -> 480000
A7: Sillas | B7: 90000 | C7: 4 | D7: =B7*C7 -> 360000
A8: Router / Networking oficina | B8: 60000 | C8: 1 | D8: =B8*C8 -> 60000
A9: Telefonos IP | B9: 2000 | C9: 0 | D9: =B9*C9 -> 0
A10: Armarios | B10: 80000 | C10: 2 | D10: =B10*C10 -> 160000
A11: Subtotal Inversiones Muebles y Utiles | D11: =SUM(D6:D10) -> 1060000
A12: Notebooks de desarrollo (5) | B12: 1200000 | C12: 5 | D12: =B12*C12 -> 6000000
A13: Servidor / NAS de desarrollo | B13: 700000 | C13: 1 | D13: =B13*C13 -> 700000
A14: Rack | B14: 7000 | C14: 0 | D14: =B14*C14 -> 0
A15: Impresora laser | B15: 6000 | C15: 0 | D15: =B15*C15 -> 0
A16: Router / switching | B16: 60000 | C16: 1 | D16: =B16*C16 -> 60000
A17: Switch 24 bocas | B17: 3000 | C17: 0 | D17: =B17*C17 -> 0
A18: Impresora 3D + banco de prototipado MVP (placas, sensores de prueba) | B18: 1500000 | C18: 1
A20: Subtotal Equipamiento | D20: =SUM(D12:D19) -> 6760000
A21: Total Inversiones | D21: =SUM(D20,D11) -> 7820000
A25: Equipamiento Producto
A27: Período | D27: Startup
A28: Concepto | B28: Costo | C28: Cantidad
A29: Sistema Gantry de vision (riel + motores + estructura) | B29: 2800000 | C29: 1 | D29: =PRODUCT(C29,B29) -> 2800000
A30: Conjunto microaspersor + solenoide por sector | B30: 12000 | C30: 1000 | D30: =PRODUCT(C30,B30) -> 12000000
A31: Nodo sensor testigo (ESP32 + humedad/EC/pH/temp/HR/luz + gabinete IP65) | B31: 190000 | C31: 10 | D31: =PRODUCT(C31,B31) -> 1900000
A32: Electrovalvula maestra (macro-zona) | B32: 48000 | C32: 10 | D32: =PRODUCT(C32,B32) -> 480000
A33: Bomba peristaltica de dosificacion | B33: 65000 | C33: 10 | D33: =PRODUCT(C33,B33) -> 650000
A34: Modulo de vision + computo edge (Jetson + camara) | B34: 380000 | C34: 1 | D34: =PRODUCT(C34,B34) -> 380000
A35: Actuador motorizado de mediasombra | B35: 130000 | C35: 10 | D35: =PRODUCT(C35,B35) -> 1300000
A36: Gateway / controlador central | B36: 450000 | C36: 1 | D36: =PRODUCT(C36,B36) -> 450000
A37: Kit energia solar + baterias (respaldo autonomo) | B37: 950000 | C37: 1 | D37: =PRODUCT(C37,B37) -> 950000
A38: Kit Starlink (antena + instalacion) | B38: 375000 | C38: 1 | D38: =PRODUCT(C38,B38) -> 375000
A39: Tablero electrico + cableado + protecciones | B39: 700000 | C39: 1 | D39: =PRODUCT(C39,B39) -> 700000
A40: Hidraulica (canos, filtros, conectores, tanques) | B40: 1100000 | C40: 1 | D40: =PRODUCT(C40,B40) -> 1100000
A41: Consumibles e imprevistos de instalacion | B41: 700000 | C41: 1 | D41: =PRODUCT(C41,B41) -> 700000
D42: =PRODUCT(C42,B42) -> 0
A44: Total Equipamiento Producto X | D44: =SUM(D29:D42) -> 23785000

Sheet Amortizaciones
A1: ='Est. Res. Proy.'!A2 -> Sistema de monitoreo, diagnostico y actuacion para viveros de yerba mate
A2: Amortizaciones
A4: Período | B4: Vida Util | C4: Amortización | D4: Amortización | E4: Valor | G4: Detalle | H4: Vida Útil
A5: Concepto | B5: meses | C5: 7 meses | D5: Acumulada | E5: Residual | G5: Hardware | H5: 3 años
A6: Escritorios | B6: 120 | C6: =(Inversiones!D6)/B6*7 -> 28000 | D6: =C6 -> 28000 | E6: =Inversiones!D6-Amortizaciones!D6 -> 452000 | G6: Software | H6: 3 años
A7: Sillas | B7: 120 | C7: =(Inversiones!D7)/B7*7 -> 21000 | D7: =C7 -> 21000 | E7: =Inversiones!D7-Amortizaciones!D7 -> 339000 | G7: Software Licencias | H7: 3 años
A8: Router Telefonia IP | B8: 120 | C8: =(Inversiones!D8)/B8*7 -> 3500 | D8: =C8 -> 3500 | E8: =Inversiones!D8-Amortizaciones!D8 -> 56500
A9: Teléfonos IP | B9: 120 | C9: =(Inversiones!D9)/B9*7 -> 0 | D9: =C9 -> 0 | E9: =Inversiones!D9-Amortizaciones!D9 -> 0
A10: Armarios | B10: 120 | C10: =(Inversiones!D10)/B10*7 -> 9333.3333 | D10: =C10 -> 9333.3333 | E10: =Inversiones!D10-Amortizaciones!D10 -> 150666.67
A11: Subtotal Inversiones Muebles y Utiles | C11: =SUM(C6:C10) -> 61833.333 | D11: =SUM(D6:D10) -> 61833.333 | E11: =SUM(E6:E10) -> 998166.67
A12: Computadoras Portátiles (Dell Vostro I3 4gb 1tb) | B12: =12*3 -> 36 | C12: =(Inversiones!D12)/B12*7 -> 1166666.7 | D12: =C12 -> 1166666.7 | E12: =Inversiones!D12-Amortizaciones!D12 -> 4833333.3
A13: Servidor | B13: 120 | C13: =(Inversiones!D13)/B13*7 -> 40833.333 | D13: =C13 -> 40833.333 | E13: =Inversiones!D13-Amortizaciones!D13 -> 659166.67
A14: Rack Servidor | B14: 120 | C14: =(Inversiones!D14)/B14*7 -> 0 | D14: =C14 -> 0 | E14: =Inversiones!D14-Amortizaciones!D14 -> 0
A15: Impresoras laser BN | B15: 120 | C15: =(Inversiones!D15)/B15*7 -> 0 | D15: =C15 -> 0 | E15: =Inversiones!D15-Amortizaciones!D15 -> 0
A16: Router | B16: 120 | C16: =(Inversiones!D16)/B16*7 -> 3500 | D16: =C16 -> 3500 | E16: =Inversiones!D16-Amortizaciones!D16 -> 56500
A17: Switch 24 bocas | B17: 120 | C17: =(Inversiones!D17)/B17*7 -> 0 | D17: =C17 -> 0 | E17: =Inversiones!D17-Amortizaciones!D17 -> 0
A18: Impresora 3D | B18: 120 | C18: =(Inversiones!D18)/B18*7 -> 0 | D18: =C18 -> 0 | E18: =Inversiones!D18-Amortizaciones!D18 -> 0
A19: Subtotal Equipamiento | C19: =SUM(C12:C18) -> 1211000 | D19: =SUM(D12:D18) -> 1211000 | E19: =SUM(E12:E18) -> 5549000
A20: Total Amortizaciones | C20: =C11+C19 -> 1272833.3 | D20: =D11+D19 -> 1272833.3

Sheet Intra Extranets
A1: FLUJO DE INGRESOS
A3: Servicios Pagos | B3: mes 1 | C3: mes 2 | D3: mes 3 | E3: mes 4 | F3: mes 5 | G3: mes 6 | H3: mes 7 | I3: mes 8 | J3: mes 9 | K3: mes 10 | L3: mes 11 | M3: mes 12 | N3: Acumulado Anual
A4: Unidades | B4: =B5/60000 -> 0 | C4: =C5/60000 -> 1 | D4: =D5/60000 -> 0 | E4: =E5/60000 -> 1 | F4: =F5/60000 -> 0 | G4: =G5/60000 -> 1 | H4: =H5/60000 -> 0 | I4: =I5/60000 -> 1 | ... M4: =M5/60000 -> 1 | N4: =SUM(B4:M4) -> 6
A5: Soluciones de Intra/Extranets | B5: 0 | C5: 60000 | D5: 0 | E5: 60000 | F5: 0 | G5: 60000 | H5: 0 | I5: 60000 | J5: 0 | K5: 60000 | L5: 0 | M5: 60000 | N5: =SUM(B5:M5) -> 360000
A6: TOTAL INGRESOS | B6: =SUM(B5) -> 0 | C6: =SUM(C5) -> 60000 | D6: =SUM(D5) -> 0 | E6: =SUM(E5) -> 60000 | F6: =SUM(F5) -> 0 | G6: =SUM(G5) -> 60000 | H6: =SUM(H5) -> 0 | I6: =SUM(I5) -> 60000 | ... N6: =SUM(N5) -> 360000
A8: FLUJO DE EGRESOS
A10: Costos por desarrollo de Servicios | B10: mes 1 | C10: mes 2 | D10: mes 3 | E10: mes 4 | F10: mes 5 | G10: mes 6 | H10: mes 7 | I10: mes 8 | J10: mes 9 | K10: mes 10 | L10: mes 11 | M10: mes 12 | N10: Acumulado Anual
A11: Soluciones de Intra/Extranets - Basado en la Cotización del Pool de Compras (Top Group) | B11: 0 | C11: 30000 | D11: 0 | E11: 30000 | F11: 0 | G11: 30000 | H11: 0 | I11: 30000 | J11: 0 | K11: 30000 | L11: 0 | M11: 30000 | N11: =SUM(B11:M11) -> 180000
A12: TOTAL COSTO DESARROLLO | B12: =SUM(B11) -> 0 | C12: =SUM(C11) -> 30000 | D12: =SUM(D11) -> 0 | E12: =SUM(E11) -> 30000 | F12: =SUM(F11) -> 0 | G12: =SUM(G11) -> 30000 | H12: =SUM(H11) -> 0 | I12: =SUM(I11) -> 30000 | ... N12: =SUM(N11) -> 180000
A14: INGRESOS NETOS INTRA/EXTRANETS | B14: =B6-B12 -> 0 | C14: =C6-C12 -> 30000 | D14: =D6-D12 -> 0 | E14: =E6-E12 -> 30000 | F14: =F6-F12 -> 0 | G14: =G6-G12 -> 30000 | H14: =H6-H12 -> 0 | I14: =I6-I12 -> 30000 | ... N14: =N6-N12 -> 180000
A16: DISTRIBUCION ESTIM. DE VENTAS | B16: mes 1 | C16: mes 2 | D16: mes 3 | E16: mes 4 | F16: mes 5 | G16: mes 6 | H16: mes 7 | I16: mes 8 | J16: mes 9 | K16: mes 10 | L16: mes 11 | M16: mes 12
A17: Comisión por ventas Directas no tel. | B17: 1 | C17: 1 | D17: 1 | E17: 1 | F17: 1 | G17: 1 | H17: 1 | I17: 1 | J17: 1 | K17: 1 | L17: 1 | M17: 1
A18: Comisión por ventas Telefónicas | B18: 0 | C18: 0 | D18: 0 | E18: 0 | F18: 0 | G18: 0 | H18: 0 | I18: 0 | J18: 0 | K18: 0 | L18: 0 | M18: 0
A19: Comisión por ventas Indirectas | B19: 0 | C19: 0 | D19: 0 | E19: 0 | F19: 0 | G19: 0 | H19: 0 | I19: 0 | J19: 0 | K19: 0 | L19: 0 | M19: 0
A20: TOTAL COMISION A CANALES | B20: =SUM(B17:B19) -> 1 | C20: =SUM(C17:C19) -> 1 | D20: =SUM(D17:D19) -> 1 | E20: =SUM(E17:E19) -> 1 | F20: =SUM(F17:F19) -> 1 | G20: =SUM(G17:G19) -> 1 | H20: =SUM(H17:H19) -> 1 | I20: =SUM(I17:I19) -> 1 | ... M20: =SUM(M17:M19) -> 1
A22: COMISIONES POR VENTAS | B22: mes 1 | C22: mes 2 | D22: mes 3 | E22: mes 4 | F22: mes 5 | G22: mes 6 | H22: mes 7 | I22: mes 8 | J22: mes 9 | K22: mes 10 | L22: mes 11 | M22: mes 12 | N22: Acumulado Anual
A23: Comisión por ventas Directas no tel. | B23: 0.05 | C23: 0.05 | D23: 0.05 | E23: 0.05 | F23: 0.05 | G23: 0.05 | H23: 0.05 | I23: 0.05 | J23: 0.05 | K23: 0.05 | L23: 0.05 | M23: 0.05
A24: Comisión por ventas Telefónicas | B24: 0.05 | C24: 0.05 | D24: 0.05 | E24: 0.05 | F24: 0.05 | G24: 0.05 | H24: 0.05 | I24: 0.05 | J24: 0.05 | K24: 0.05 | L24: 0.05 | M24: 0.05
A25: Comisión por ventas Indirectas | B25: 0.05 | C25: 0.05 | D25: 0.05 | E25: 0.05 | F25: 0.05 | G25: 0.05 | H25: 0.05 | I25: 0.05 | J25: 0.05 | K25: 0.05 | L25: 0.05 | M25: 0.05
A26: TOTAL COMISION A CANALES | B26: =B6*(B17*B23+B18*B24+B19*B25) -> 0 | C26: =C6*(C17*C23+C18*C24+C19*C25) -> 3000 | D26: =D6*(D17*D23+D18*D24+D19*D25) -> 0 | E26: =E6*(E17*E23+E18*E24+E19*E25) -> 3000 | F26: =F6*(F17*F23+F18*F24+F19*F25) -> 0 | G26: =G6*(G17*G23+G18*G24+G19*G25) -> 3000 | H26: =H6*(H17*H23+H18*H24+H19*H25) -> 0 | I26: =I6*(I17*I23+I18*I24+I19*I25) -> 3000 | ... M26: =M6*(M17*M23+M18*M24+M19*M25) -> 3000 | N26: =SUM(B26:M26) -> 18000

Sheet Cuadro de Resultados
A1: CUADRO DE RESULTADOS
A3: FLUJO DE FONDOS PROYECTADO A 12 MESES
B5: Momento Inicial | C5: Mes 1 | D5: Mes 2 | E5: Mes 3 | F5: Mes 4 | G5: Mes 5 | H5: Mes 6 | I5: Mes 7 | J5: Mes 8 | K5: Mes 9 | L5: Mes 10 | M5: Mes 11 | N5: Mes 12
A7: TOTAL INGRESOS | B7: 0 | C7: =#REF! -> #REF! | D7: =#REF! -> #REF! | E7: =#REF! -> #REF! | F7: =#REF! -> #REF! | G7: =#REF! -> #REF! | H7: =#REF! -> #REF! | I7: =#REF! -> #REF! | J7: =#REF! -> #REF! | ... N7: =#REF! -> #REF!
A9: TOTAL EGRESOS | B9: =#REF! -> #REF! | C9: =#REF! -> #REF! | D9: =#REF! -> #REF! | E9: =#REF! -> #REF! | F9: =#REF! -> #REF! | G9: =#REF! -> #REF! | H9: =#REF! -> #REF! | I9: =#REF! -> #REF! | ... N9: =#REF! -> #REF!
A11: RESULTADO NETO | B11: =B7-B9 -> #REF! | C11: =C7-C9 -> #REF! | D11: =D7-D9 -> #REF! | E11: =E7-E9 -> #REF! | F11: =F7-F9 -> #REF! | G11: =G7-G9 -> #REF! | H11: =H7-H9 -> #REF! | I11: =I7-I9 -> #REF! | ... N11: =N7-N9 -> #REF!
A13: TOTAL INVERSIONES | B13: =#REF! -> #REF! | C13: =#REF! -> #REF! | D13: =#REF! -> #REF! | E13: =#REF! -> #REF! | F13: =#REF! -> #REF! | G13: =#REF! -> #REF! | H13: =#REF! -> #REF! | I13: =#REF! -> #REF! | ... N13: =#REF! -> #REF!
A15: TOTAL DEPRECIACIONES | B15: =#REF! -> #REF! | C15: =#REF! -> #REF! | D15: =#REF! -> #REF! | E15: =#REF! -> #REF! | F15: =#REF! -> #REF! | G15: =#REF! -> #REF! | H15: =#REF! -> #REF! | I15: =#REF! -> #REF! | ... N15: =#REF! -> #REF!
A17: GANANCIA A. IMPUESTOS (EBIT) | B17: =B11-B13-B15 -> #REF! | C17: =C11-C13-C15 -> #REF! | D17: =D11-D13-D15 -> #REF! | E17: =E11-E13-E15 -> #REF! | F17: =F11-F13-F15 -> #REF! | G17: =G11-G13-G15 -> #REF! | H17: =H11-H13-H15 -> #REF! | I17: =I11-I13-I15 -> #REF! | ... N17: =N11-N13-N15 -> #REF!
A19: GANANCIA D. IMPUESTOS | B19: =#REF! -> #REF! | C19: =#REF! -> #REF! | D19: =#REF! -> #REF! | E19: =#REF! -> #REF! | F19: =#REF! -> #REF! | G19: =#REF! -> #REF! | H19: =#REF! -> #REF! | I19: =#REF! -> #REF! | ... N19: =#REF! -> #REF!
A21: EBITDA | C21: =C7-C9-C13 -> #REF! | D21: =D7-D9-D13 -> #REF! | E21: =E7-E9-E13 -> #REF! | F21: =F7-F9-F13 -> #REF! | G21: =G7-G9-G13 -> #REF! | H21: =H7-H9-H13 -> #REF! | I21: =I7-I9-I13 -> #REF! | J21: =J7-J9-J13 -> #REF! | ... N21: =N7-N9-N13 -> #REF!
B23: VAN (10% anual) = | C23: {=NPV(((1+0.1)^(1/12)-1),B19:N19)} -> #REF! | D23: =(1+0.1)^(1/12)-1 -> 0.0079741404 | E23: T.E.M
B25: TIR = | C25: =IRR(B19:N19,0.01) -> #VALUE!
A27: PUNTO DE EQUILIBRIO (V.T.D. 0,8% mensual) | B27: =B19 -> #REF! | C27: =C19+B19*(1+D23)^2 -> #REF! | D27: =D19+C19*(1+D23)^2+B19*(1+D23)^3 -> #REF! | E27: =E19+D19*(1+D23)^2+C19*(1+D23)^3+B19*(1+D23)^4 -> #REF! | F27: =F19+E19*(1+D23)^2+D19*(1+D23)^3+C19*(1+D23)^4+B19*(1+D23)^5 -> #REF! | G27: =G19+F19*(1+$D23)^2+E19*(1+$D23)^3+D19*(1+$D23)^4+C19*(1+$D23)^5+B19*(1+$D23)^6 -> #REF! | H27: =H19+G19*(1+$D23)^2+F19*(1+$D23)^3+E19*(1+$D23)^4+D19*(1+$D23)^5+C19*(1+$D23)^6+B19*(1+$D23)^7 -> #REF! | I27: =I19+H19*(1+$D23)^2+G19*(1+$D23)^3+F19*(1+$D23)^4+E19*(1+$D23)^5+D19*(1+$D23)^6+C19*(1+$D23)^7+B19*(1+$D23)^8 -> #REF! | J27: =J19+I19*(1+$D23)^2+H19*(1+$D23)^3+G19*(1+$D23)^4+F19*(1+$D23)^5+E19*(1+$D23)^6+D19*(1+$D23)^7+C19*(1+$D23)^8+B19*(1+$D23)^9 -> #REF! | K27: =K19+J19*(1+$D23)^2+I19*(1+$D23)^3+H19*(1+$D23)^4+G19*(1+$D23)^5+F19*(1+$D23)^6+E19*(1+$D23)^7+D19*(1+$D23)^8+C19*(1+$D23)^9+B19*(1+$D23)^10 -> #REF! | L27: =L19+K19*(1+$D23)^2+J19*(1+$D23)^3+I19*(1+$D23)^4+H19*(1+$D23)^5+G19*(1+$D23)^6+F19*(1+$D23)^7+E19*(1+$D23)^8+D19*(1+$D23)^9+C19*(1+$D23)^10+B19*(1+$D23)^11 -> #REF! | M27: =M19+L19*(1+$D23)^2+K19*(1+$D23)^3+J19*(1+$D23)^4+I19*(1+$D23)^5+H19*(1+$D23)^6+G19*(1+$D23)^7+F19*(1+$D23)^8+E19*(1+$D23)^9+D19*(1+$D23)^10+C19*(1+$D23)^11+B19*(1+$D23)^12 -> #REF! | N27: =N19+M19*(1+$D23)^2+L19*(1+$D23)^3+K19*(1+$D23)^4+J19*(1+$D23)^5+I19*(1+$D23)^6+H19*(1+$D23)^7+G19*(1+$D23)^8+F19*(1+$D23)^9+E19*(1+$D23)^10+D19*(1+$D23)^11+C19*(1+$D23)^12+B19*(1+$D23)^13 -> #REF!
